Workbook

Sheet SAMPUL
B8: DINAS PENDIDIKAN PEMUDA DAN OLAHRAGA
B9: KOTA YOGYAKARTA
B12: ANGGARAN PENDAPATAN DAN BELANJA SEKOLAH
B13: SD NEGERI RANDUSARI
B15: TAHUN ANGGARAN 2026
B17: Pengguna Anggaran :
C19: a. Nama | F19: : JUMADI, S.Pd.SD
C21: b. NIP | F21: : 19710727 199103 1 003
C23: c. Jabatan | F23: : Kepala Sekolah
C26: KODE | F26: NAMA FORMULIR
C27: DPK-SP | F27: Ringkasan Anggaran Pendapatan dan Belanja Sekolah
C28: DPK-SP 1 | F28: Rincian Anggaran Pendapatan
C29: DPK-SP 5 | F29: Rekap Anggaran Belanja
C30: DPK-SP 5.1 | F30: Rincian Anggaran Belanja
C31: DPK-SP 5.1.1 | F31: Rincian Dokumen Pelaksanaan Kegiatan Belanja Program dan Per Kegiatan Satuan Pendidikan

Sheet lembar pengesahan
B8: LEMBAR PERSETUJUAN
B11: ANGGARAN PENDAPATAN DAN BELANJA SEKOLAH
B12: SD NEGERI RANDUSARI
B14: TAHUN ANGGARAN 2026
H16: Yogyakarta, 11 Februari 2026
C17: Ketua Komite | H17: Kepala Sekolah
C22: Jumianto | H22: Jumadi, S.Pd.SD
H23: NIP 19710727 199103 1 003
B26: Menyetujui
B27: Kepala Dinas Pendidikan Pemuda & Olahraga Kota Yogyakarta
B32: Budi Santosa Asrori, SE., M.Si
B33: NIP. 19700915 199403 1 009
C38: No | D38: Nama | G38: Jabatan | I38: Paraf
C39: 1 | D39: Sujimin, S.Pd, | G39: Pengawas
C40: 2 | G40: Verifikator
C41: 3 | D41: Dra Tyasning Handayani Shanti | G41: Sekretaris Dinas

Sheet DPA SP
K1: FORMULIR DPK-SP
B9: Urusan | G9: : Pendidikan
B11: Satuan Pendidikan | G11: : SD Negeri Randusari
B14: Ringkasan Anggaran Pendapatan dan Belanja Sekolah
B15: Tahun Anggaran 2026
B17: Kode | E17: Uraian | K17: Anggaran
B18: 1 | E18: 2 | K18: 3
B19: 1 | E19: PENDAPATAN | K19: =SUM(K20:K25) -> 944848847
B20: 1 | C20: 1 | E20: APBN | K20: ='DPA SP 1'!L23 -> 81000000
B21: 1 | C21: 2 | E21: APBD DIY | K21: ='DPA SP 1'!L26 -> 0
B22: 1 | C22: 3 | E22: APBD Kota Yogyakarta | K22: ='DPA SP 1'!L28 -> 863627117
B23: 1 | C23: 4 | E23: Pendapatan dari Masyarakat | K23: ='DPA SP 1'!L32 -> 0
B24: 1 | C24: 5 | E24: Lain-lain | K24: ='DPA SP 1'!L35 -> 0
B25: 1 | C25: 6 | E25: Sisa Lebih Perhitungan Anggaran Tahun Lalu | K25: ='DPA SP 1'!L38 -> 221730
B27: 5 | E27: BELANJA | K27: =K28+K31 -> #REF!
B28: 5 | C28: 1 | E28: Belanja Operasi | K28: =SUM(K29:K30) -> #REF!
B29: 5 | C29: 1 | D29: 01 | E29: Belanja Pegawai | K29: ='DPA SP 5 1'!N76 -> 4200000
B30: 5 | C30: 1 | D30: 02 | E30: Belanja Barang dan Jasa | K30: ='DPA SP 5 1'!N82+'DPA SP 5 1'!N77+'DPA SP 5 1'!N73+'DPA SP 5 1'!N70+'DPA SP 5 1'!N65+'DPA SP 5 1'!#REF!+'DPA SP 5 1'!N57+'DPA SP 5 1'!N54+'DPA SP 5 1'!N46+'DPA SP 5 1'!N41+'DPA SP 5 1'!N38+'DPA SP 5 1'!N35 -> #REF!
B31: 5 | C31: 2 | E31: Belanja Modal | K31: =SUM(K32:K33) -> #REF!
B32: 5 | C32: 2 | D32: 02 | E32: Belanja Modal Peralatan dan Mesin | K32: ='DPA SP 5 1'!#REF!+'DPA SP 5 1'!N60 -> #REF!
B33: 5 | C33: 2 | D33: 05 | E33: Belanja Modal Aset Tetap Lainnya | K33: ='DPA SP 5 1'!N51 -> 15750000
E36: SURPLUS/DEFISIT | K36: =K19-K27 -> #REF!
D39: Mengetahui
D40: Ketua Komite Sekolah | J40: Kepala Sekolah
D44: Jumianto | J44: Jumadi, S.Pd.SD
J45: NIP. 19710727 199103 1 003

Sheet DPA SP 1
L1: FORMULIR DPK-SP 1
B8: DINAS PENDIDIKAN PEMUDA DAN OLAHRAGA
B9: KOTA YOGYAKARTA
B10: TAHUN ANGGARAN 2024
B12: Urusan | H12: : Pendidikan
B14: Satuan Pendidikan | H14: : SD Negeri Randusari
B17: Rincian Anggaran Pendapatan
B18: Tahun Anggaran 2026
B20: Kode | F20: Uraian | H20: Rincian | I20: Volume | J20: Satuan | K20: Harga Satuan | L20: Anggaran
B21: 1 | F21: 2 | H21: 3 | I21: 4 | J21: 5 | K21: 6 | L21: 7
B22: 1 | F22: PENDAPATAN | L22: =+L23+L26+L28+L32+L35+L38 -> 944848847
B23: 1 | C23: 1 | F23: APBN | L23: =+L24 -> 81000000
B24: 1 | C24: 1 | D24: 1 | F24: BOSN 2026 | L24: 81000000
B26: 1 | C26: 2 | F26: APBD DIY | L26: 0
B28: 1 | C28: 3 | F28: APBD Kota Yogyakarta | L28: =SUM(L29:L30) -> 863627117
B29: 1 | C29: 3 | D29: 1 | F29: Gaji dan Tunjangan | L29: 721127117
B30: 1 | C30: 3 | D30: 2 | F30: BOSDA 2026 | L30: 142500000
B32: 1 | C32: 4 | F32: Pendapatan dari Masyarakat | L32: =+L33 -> 0
B33: 1 | C33: 4 | D33: 1 | F33: Sumbangan Sukarela
B35: 1 | C35: 5 | F35: Lain-lain | L35: =+L36 -> 0
B36: 1 | C36: 5 | D36: 1 | F36: Pendapatan Sewa
B38: 1 | C38: 6 | F38: Sisa lebih perhitungan anggaran tahun lalu | L38: =L40+L39 -> 221730
B39: 1 | C39: 6 | D39: 1 | F39: Silpa BOSN 2024 | L39: 79000
B40: 1 | C40: 6 | D40: 2 | F40: Silpa BOSN 2021 | L40: 142730
F42: Jumlah | L42: =+L22 -> 944848847
E44: Mengetahui
E45: Ketua Komite Sekolah | K45: Kepala Sekolah
E49: Jumianto | K49: Jumadi, S.Pd.SD
K50: NIP. 19710727 199103 1 003

Sheet DPA SP 5
L1: FORMULIR DPK-SP 5
B8: DINAS PENDIDIKAN PEMUDA DAN OLAHRAGA
B9: KOTA YOGYAKARTA
B10: TAHUN ANGGARAN 2026
B12: Urusan | H12: : Pendidikan
B14: Satuan Pendidikan | H14: : SD Negeri Randusari
B17: Rekap Anggaran Belanja
B18: Tahun Anggaran 2026
B20: Kode | F20: Uraian | L20: Anggaran
B21: 1 | F21: 2 | L21: 7
B22: 5 | F22: Belanja | L22: =L23+L26+L28+L33+L36+L42+L45+L50 -> 221637000
B23: 5 | C23: 1 | F23: Program Pengembangan Kompetensi Lulusan | L23: 0
F24: Honorarium Penyelenggara Ujian | L24: ='DPA SP 5 1'!N24 -> 8083000
B26: 5 | C26: 2 | F26: Program Pengembangan Standar Isi | L26: 0
B28: 5 | C28: 3 | F28: Program Pengembangan Standar Proses | L28: =SUM(L29:L31) -> 51855000
B29: 5 | C29: 3 | D29: 1 | F29: Kegiatan Pembiayaan Penerimaan Peserta Didik Baru | L29: ='DPA SP 5 1'!N33 -> 3755000
B30: 5 | C30: 3 | D30: 2 | F30: Kegiatan Pembiayaan Pengembangan Perpustakaan | L30: ='DPA SP 5 1'!N36 -> 1080000
B31: 5 | C31: 3 | D31: 3 | F31: Kegiatan Pembiayaan Kegiatan Pembelajaran dan Ekstrakurikuler | L31: ='DPA SP 5 1'!N39 -> 47020000
B33: 5 | C33: 4 | F33: Program Pengembangan Pendidik dan Tenaga Kependidikan | L33: =SUM(L34:L34) -> 10420000
B34: 5 | C34: 4 | D34: 2 | F34: Kegiatan Pembiayaan Pengembangan Profesi Guru dan Tenaga Kependidikan | L34: ='DPA SP 5 1'!N44 -> 10420000
B36: 5 | C36: 5 | F36: Program Pengembangan Sarana dan Prasarana Sekolah | L36: =SUM(L37:L40) -> 114047200
B37: 5 | C37: 5 | D37: 1 | F37: Kegiatan Pembiayaan Pengembangan Perpustakaan | L37: ='DPA SP 5 1'!N49 -> 15750000
B38: 5 | C38: 5 | D38: 3 | F38: Kegiatan Pembiayaan Administrasi Kegiatan Sekolah | L38: ='DPA SP 5 1'!N52 -> 1500000
B39: 5 | C39: 5 | D39: 5 | F39: Kegiatan Pembiayaan Pemeliharaan Sarana dan Prasarana | L39: ='DPA SP 5 1'!N55 -> 35261800
B40: 5 | C40: 5 | D40: 7 | F40: Kegiatan Penyediaan Alat Multimedia Pembelajaran | L40: ='DPA SP 5 1'!N58 -> 61535400
B42: 5 | C42: 6 | F42: Program Pengembangan Standar Pengelolaan | L42: =L43 -> 7002000
B43: 5 | C43: 6 | D43: 2 | F43: Kegiatan Pembiayaan Administrasi Kegiatan Sekolah | L43: ='DPA SP 5 1'!N63 -> 7002000
B45: 5 | C45: 7 | F45: Program Pengembangan Pembiayaan | L45: =SUM(L46:L48) -> 36312800
B46: 5 | C46: 7 | D46: 1 | F46: Kegiatan Pembiayaan Administrasi Kegiatan Sekolah | L46: ='DPA SP 5 1'!N68 -> 11490000
B47: 5 | C47: 7 | D47: 2 | F47: Kegiatan Pembiayaan Langganan Daya dan/atau Jasa | L47: ='DPA SP 5 1'!N71 -> 13722800
B48: 5 | C48: 7 | D48: 5 | F48: Kegiatan Pembiayaan untuk Pembayaran Honor | L48: ='DPA SP 5 1'!N74 -> 11100000
B50: 5 | C50: 8 | F50: Program Pengembangan dan Implementasi Sistem Penilaian | L50: =L51 -> 2000000
B51: 5 | C51: 8 | D51: 2 | F51: Kegiatan Pembiayaan Asesmen/Evaluasi Pembelajaran dan Ekstrakurikuler | L51: ='DPA SP 5 1'!N80 -> 2000000
F53: Jumlah | L53: =L24+L28+L33+L36+L42+L45+L50 -> 229720000
E55: Mengetahui
E56: Ketua Komite Sekolah | K56: Kepala Sekolah
E60: Jumianto | K60: Jumadi, S.Pd.SD
K61: NIP. 19710727 199103 1 003

Sheet DPA SP 5 1
N1: FORMULIR DPK-SP 5.1
B8: DINAS PENDIDIKAN PEMUDA DAN OLAHRAGA
B9: KOTA YOGYAKARTA
B10: TAHUN ANGGARAN 2026
B12: Urusan | J12: : Pendidikan
B14: Satuan Pendidikan | J14: : SD Negeri Randusari
B17: Rincian Anggaran Belanja
B18: Tahun Anggaran 2026
B20: Kode | H20: Uraian | N20: Anggaran
B21: 1 | H21: 2 | N21: 7
B22: 5 | H22: Belanja | N22: =N23+N32+N43+N48+N62+N67+N79+N28 -> 231000000
B23: 5 | C23: 1 | H23: Program Pengembangan Kompetensi Lulusan | N23: =N24 -> 8083000
H24: Honorarium Penyelenggara Ujian | N24: ='5.1.2'!W42 -> 8083000
B28: 5 | C28: 2 | H28: Program Pengembangan Standar Isi | N28: =N29+N30 -> 1280000
B29: 5 | C29: 2 | D29: 1 | H29: Belanja Operasi | N29: ='5.2.1'!W37 -> 480000
B30: 5 | C30: 2 | D30: 1 | H30: Belanja Barang dan Jasa | N30: ='5.2.1'!W45 -> 800000
B32: 5 | C32: 3 | H32: Program Pengembangan Standar Proses | N32: =N33+N36+N39 -> 51855000
B33: 5 | C33: 3 | D33: 1 | H33: Kegiatan Pembiayaan Penerimaan Peserta Didik Baru | N33: =+N34 -> 3755000
B34: 5 | C34: 3 | D34: 1 | E34: 5 | F34: 1 | H34: Belanja Operasi | N34: =+N35 -> 3755000
B35: 5 | C35: 3 | D35: 1 | E35: 5 | F35: 1 | G35: 02 | H35: Belanja Barang dan Jasa | N35: ='5.3.1'!W59 -> 3755000
B36: 5 | C36: 3 | D36: 2 | H36: Kegiatan Pembiayaan Pengembangan Perpustakaan | N36: =N37 -> 1080000
B37: 5 | C37: 3 | D37: 2 | E37: 5 | F37: 1 | H37: Belanja Operasi | N37: =N38 -> 1080000
B38: 5 | C38: 3 | D38: 2 | E38: 5 | F38: 1 | G38: 02 | H38: Belanja Barang dan Jasa | N38: ='5.3.2'!W39 -> 1080000
B39: 5 | C39: 3 | D39: 3 | H39: Kegiatan Pembiayaan Kegiatan Pembelajaran dan Ekstrakurikuler | N39: =N40 -> 47020000
B40: 5 | C40: 3 | D40: 3 | E40: 5 | F40: 1 | H40: Belanja Operasi | N40: =N41 -> 47020000
B41: 5 | C41: 3 | D41: 3 | E41: 5 | F41: 1 | G41: 02 | H41: Belanja Barang dan Jasa | N41: ='5.3.3'!W41 -> 47020000
B43: 5 | C43: 4 | H43: Program Pengembangan Pendidik dan Tenaga Kependidikan | N43: =N44 -> 10420000
B44: 5 | C44: 4 | D44: 2 | H44: Kegiatan Pembiayaan Pengembangan Profesi Guru dan Tenaga Kependidikan | N44: =+N45 -> 10420000
B45: 5 | C45: 4 | D45: 2 | E45: 5 | F45: 1 | H45: Belanja Operasi | N45: =+N46 -> 10420000
B46: 5 | C46: 4 | D46: 2 | E46: 5 | F46: 1 | G46: 02 | H46: Belanja Barang dan Jasa | N46: ='5.4.2'!W39 -> 10420000
B48: 5 | C48: 5 | H48: Program Pengembangan Sarana dan Prasarana Sekolah | N48: =N49+N52+N55+N58 -> 114047200
B49: 5 | C49: 5 | D49: 1 | H49: Kegiatan Pembiayaan Pengembangan Perpustakaan | N49: =N50 -> 15750000
B50: 5 | C50: 5 | D50: 1 | E50: 5 | F50: 2 | H50: Belanja Modal | N50: =+N51 -> 15750000
B51: 5 | C51: 5 | D51: 1 | E51: 5 | F51: 2 | G51: 05 | H51: Belanja Modal Aset Tetap Lainnya | N51: ='5.5.1'!W39 -> 15750000
B52: 5 | C52: 5 | D52: 3 | H52: Kegiatan Pembiayaan Administrasi Kegiatan Sekolah | N52: =N53 -> 1500000
B53: 5 | C53: 5 | D53: 3 | E53: 5 | F53: 1 | H53: Belanja Operasi | N53: =N54 -> 1500000
B54: 5 | C54: 5 | D54: 3 | E54: 5 | F54: 1 | G54: 02 | H54: Belanja Barang dan Jasa | N54: ='5.5.3'!W39 -> 1500000
B55: 5 | C55: 5 | D55: 5 | H55: Kegiatan Pembiayaan Pemeliharaan Sarana dan Prasarana | N55: =N56 -> 35261800
B56: 5 | C56: 5 | D56: 5 | E56: 5 | F56: 1 | H56: Belanja Operasi | N56: =N57 -> 35261800
B57: 5 | C57: 5 | D57: 5 | E57: 5 | F57: 1 | G57: 02 | H57: Belanja Barang dan Jasa | N57: ='5.5.5'!W41 -> 35261800
...

Sheet 5.1.2
V3: DPK-SP 5.1.1
W4: 1
A5: KOTA YOGYAKARTA
A6: TAHUN ANGGARAN 2026
A7: Satuan Pendidikan | J7: : | K7: SD Negeri Randusari
A8: Program | J8: : | K8: 5.8 Pengembangan dan Implementasi Sistem Penilaian
A9: Kegiatan | J9: : | K9: 5.8.2 Kegiatan Pembiayaan Asesmen/Evaluasi Pembelajaran dan Ekstrakurikuler
A10: Waktu Pelaksanaan | J10: : | K10: Januari s.d Desember
A11: Lokasi Kegiatan | J11: : | K11: SD Negeri Randusari
A12: Sumber Dana | J12: : | K12: BOSDA Rp8.050.000,00
A13: Indikator & Tolok Ukur Belanja
A14: Indikator | J14: Tolok Ukur Kinerja | V14: Target Kinerja
A15: Capaian Program | J15: :
A16: Masukan | J16: : | K16: Dana
J17: : | K17: SDM
J18: : | K18: Sarana Prasarana
J19: : | K19: Metode Kerja
A20: Keluaran | J20: : | K20: 1. Penyusunan Kisi-kisi Ujian Sekolah
K21: 2. Penyusunan Soal Ujian Sekolah
K22: 3. Pelaksanaan Penilaian Ujian Sekolah
K23: 4. Simulasi dan Pelaksanaan Ujian Nasional Berbasis Komputer (UNBK)
A24: Hasil | J24: :
A28: Kelompok Sasaran Kegiatan | J28: :
A29: Rincian Dokumen Pelaksanaan Kegiatan Belanja
A30: Menurut Program dan Per Kegiatan Satuan Pendidikan
A31: KODE REKENING | I31: U R A I A N | L31: RINCIAN PERHITUNGAN | W31: JUMLAH | X31: Ket | Y31: tata kala perencanaan anggaran bulanan | AK31: JUMLAH | AL31: tata kala pengeluaran anggaran bulanan | AX31: JUMLAH | AY31: SISA
L33: Rincian | T33: Volume | U33: Satuan | V33: Harga Satuan
W34: (Rp) | Y34: 1 | Z34: 2 | AA34: 3 | AB34: 4 | AC34: 5 | AD34: 6 | AE34: 7 | AF34: 8 | AG34: 9 | AH34: 10 | AI34: 11 | AJ34: 12 | AL34: 1 | AM34: 2 | AN34: 3 | AO34: 4 | AP34: 5 | AQ34: 6 | AR34: 7 | AS34: 8 | AT34: 9 | AU34: 10 | AV34: 11 | AW34: 12
A36: 1 | I36: 2 | L36: 3 | T36: 4 | U36: 5 | V36: 6 | W36: 7 = (4x6) | X36: 8
B37: 5 | J37: BELANJA | W37: =W38 -> 8083000
B38: 5 | C38: 1 | J38: BELANJA OPERASI | W38: =W39 -> 8083000
B39: 5 | C39: 1 | D39: 02 | J39: BELANJA BARANG DAN JASA | W39: =W40 -> 8083000
B40: 5 | C40: 1 | D40: 02 | E40: 02 | J40: Belanja Jasa | W40: =W41 -> 8083000
B41: 5 | C41: 1 | D41: 02 | E41: 02 | F41: 01 | J41: Belanja Jasa Kantor | W41: =W42 -> 8083000
B42: 5 | C42: 1 | D42: 02 | E42: 02 | F42: 01 | G42: 0009 | J42: Honorarium Penyelenggara Ujian | W42: =SUM(W43:W63) -> 8083000
J43: Instruktur Pendalaman Materi Kelas VI | L43: 2 | M43: org | N43: x | O43: 4 | P43: jpl | Q43: x | R43: 3 | S43: bln | T43: =L43*O43*R43 -> 24 | U43: ob | V43: 40000 | W43: =T43*V43 -> 960000 | X43: BOSDA | AK43: =SUM(Y43:AJ43) -> 0 | AX43: =SUM(AL43:AW43) -> 0 | AY43: =AK43-AX43 -> 0
J44: Tim ASPD
J45: Ketua | O45: 1 | P45: org | Q45: x | R45: 3 | S45: bln | T45: =O45*R45 -> 3 | U45: ob | V45: 75000 | W45: =T45*V45 -> 225000 | X45: BOSDA | AK45: =SUM(Y45:AJ45) -> 0 | AX45: =SUM(AL45:AW45) -> 0 | AY45: =AK45-AX45 -> 0
J46: Sekretaris | O46: 1 | P46: org | Q46: x | R46: 3 | S46: bln | T46: =O46*R46 -> 3 | U46: ob | V46: 65000 | W46: =T46*V46 -> 195000 | X46: BOSDA | AK46: =SUM(Y46:AJ46) -> 0 | AX46: =SUM(AL46:AW46) -> 0 | AY46: =AK46-AX46 -> 0
J47: Anggota | O47: 1 | P47: org | Q47: x | R47: 3 | S47: bln | T47: =O47*R47 -> 3 | U47: ob | V47: 60000 | W47: =T47*V47 -> 180000 | X47: BOSDA | AK47: =SUM(Y47:AJ47) -> 0 | AX47: =SUM(AL47:AW47) -> 0 | AY47: =AK47-AX47 -> 0
...

Sheet 5.2.1
V3: DPK-SP 5.1.1
W4: 1
A5: KOTA YOGYAKARTA
A6: TAHUN ANGGARAN 2026
A7: Satuan Pendidikan | J7: : | K7: SD Negeri Randusari
A8: Program | J8: : | K8: 5.2 Penyusunan Dokumen Kurikulum
A9: Kegiatan | J9: : | K9: 5.2 Cetak Dokumen
A10: Waktu Pelaksanaan | J10: : | K10: Januari s.d Desember
A11: Lokasi Kegiatan | J11: : | K11: SD Negeri Randusari
A12: Sumber Dana | J12: : | K12: BOSDA Rp 480.000
A13: Indikator & Tolok Ukur Belanja
A14: Indikator | J14: Tolok Ukur Kinerja | V14: Target Kinerja
A15: Capaian Program | J15: :
A16: Masukan | J16: : | K16: Dana
J17: : | K17: SDM
J18: : | K18: Sarana Prasarana
J19: : | K19: Metode Kerja
A20: Keluaran | J20: : | K20: 1. Penyusunan Kurikulum
K21: 2. Penyusunan Perangkat Ajar
A24: Hasil | J24: :
A28: Kelompok Sasaran Kegiatan | J28: :
A29: Rincian Dokumen Pelaksanaan Kegiatan Belanja
A30: Menurut Program dan Per Kegiatan Satuan Pendidikan
A31: KODE REKENING | I31: U R A I A N | L31: RINCIAN PERHITUNGAN | W31: JUMLAH | X31: Ket | Y31: tata kala perencanaan anggaran bulanan | AK31: JUMLAH | AL31: tata kala pengeluaran anggaran bulanan | AX31: JUMLAH | AY31: SISA
L33: Rincian | T33: Volume | U33: Satuan | V33: Harga Satuan
W34: (Rp) | Y34: 1 | Z34: 2 | AA34: 3 | AB34: 4 | AC34: 5 | AD34: 6 | AE34: 7 | AF34: 8 | AG34: 9 | AH34: 10 | AI34: 11 | AJ34: 12 | AL34: 1 | AM34: 2 | AN34: 3 | AO34: 4 | AP34: 5 | AQ34: 6 | AR34: 7 | AS34: 8 | AT34: 9 | AU34: 10 | AV34: 11 | AW34: 12
A36: 1 | I36: 2 | L36: 3 | T36: 4 | U36: 5 | V36: 6 | W36: 7 = (4x6) | X36: 8
B37: 5 | J37: BELANJA | W37: =W38 -> 480000
B38: 5 | C38: 2 | J38: BELANJA OPERASI | W38: =W39 -> 480000
B39: 5 | C39: 2 | D39: 01 | J39: BELANJA BARANG DAN JASA | W39: =W40 -> 480000
B40: 5 | C40: 1 | D40: 02 | E40: 02 | W40: =W41 -> 480000
W41: =W42 -> 480000
J42: Belanja Cetak kurikulum | U42: 1600 | V42: 300 | W42: =U42*V42 -> 480000 | X42: BOSDA
AK43: =SUM(Y43:AJ43) -> 0 | AX43: =SUM(AL43:AW43) -> 0 | AY43: =AK43-AX43 -> 0
B45: 5 | C45: 2 | D45: 01 | E45: 01 | J45: Belanja Jasa | W45: =W46 -> 800000 | AK45: =SUM(Y45:AJ45) -> 0 | AX45: =SUM(AL45:AW45) -> 0 | AY45: =AK45-AX45 -> 0
B46: 5 | C46: 2 | D46: 01 | E46: 01 | F46: 01 | J46: Belanja Jasa Kantor | W46: =W47 -> 800000 | AK46: =SUM(Y46:AJ46) -> 0 | AX46: =SUM(AL46:AW46) -> 0 | AY46: =AK46-AX46 -> 0
B47: 5 | C47: 2 | D47: 01 | E47: 01 | F47: 01 | G47: 00 | J47: Honorarium Tim Pelaksana Kegiatan dan Sekretariat Tim Pelaksana Kegiatan | W47: =SUM(W49:W51) -> 800000 | AK47: =SUM(Y47:AJ47) -> 0 | AX47: =SUM(AL47:AW47) -> 0 | AY47: =AK47-AX47 -> 0
J48: Tim Pengembang Kurikulum | AK48: =SUM(Y48:AJ48) -> 0 | AX48: =SUM(AL48:AW48) -> 0 | AY48: =AK48-AX48 -> 0
J49: Ketua | O49: 1 | P49: org | Q49: x | R49: 2 | S49: bln | T49: =R49*O49 -> 2 | U49: ob | V49: 175000 | W49: =V49*T49 -> 350000 | X49: BOSDA
J50: Sekretaris | O50: 1 | P50: org | Q50: x | R50: 2 | S50: bln | T50: =R50*O50 -> 2 | U50: ob | V50: 125000 | W50: =V50*T50 -> 250000 | X50: BOSDA | AK50: =SUM(Y50:AJ50) -> 0 | AX50: =SUM(AL50:AW50) -> 0 | AY50: =AK50-AX50 -> 0
...

Sheet 5.3.1
V3: DPK-SP 5.1.1
W4: 1
A5: KOTA YOGYAKARTA
A6: TAHUN ANGGARAN 2026
A7: Satuan Pendidikan | J7: : | K7: SD Negeri Randusari
A8: Program | J8: : | K8: 5.3 Pengembangan Standar Proses
A9: Kegiatan | J9: : | K9: 5.3.1 Pembiayaan Penerimaan Peserta Didik Baru
A10: Waktu Pelaksanaan | J10: : | K10: April, Juni
A11: Lokasi Kegiatan | J11: : | K11: SD Negeri Randusari
A12: Sumber Dana | J12: : | K12: BOSDA Rp3.075.000,00
A13: Indikator & Tolok Ukur Belanja
A14: Indikator | J14: Tolok Ukur Kinerja | V14: Target Kinerja
A15: Capaian Program | J15: :
A16: Masukan | J16: : | K16: Dana
J17: : | K17: SDM
J18: : | K18: Sarana Prasarana
J19: : | K19: Metode Kerja
A20: Keluaran | J20: : | K20: 1. Pelaksanaan Pendaftaran Peserta Didik Baru (PPDB)
A24: Hasil | J24: :
A28: Kelompok Sasaran Kegiatan | J28: :
A29: Rincian Dokumen Pelaksanaan Kegiatan Belanja
A30: Menurut Program dan Per Kegiatan Satuan Pendidikan
A31: KODE REKENING | I31: U R A I A N | L31: RINCIAN PERHITUNGAN | W31: JUMLAH | X31: Ket | Y31: tata kala perencanaan anggaran bulanan | AK31: JUMLAH | AL31: tata kala pengeluaran anggaran bulanan | AX31: JUMLAH | AY31: SISA
L33: Rincian | T33: Volume | U33: Satuan | V33: Harga Satuan
W34: (Rp) | Y34: 1 | Z34: 2 | AA34: 3 | AB34: 4 | AC34: 5 | AD34: 6 | AE34: 7 | AF34: 8 | AG34: 9 | AH34: 10 | AI34: 11 | AJ34: 12 | AL34: 1 | AM34: 2 | AN34: 3 | AO34: 4 | AP34: 5 | AQ34: 6 | AR34: 7 | AS34: 8 | AT34: 9 | AU34: 10 | AV34: 11 | AW34: 12
A36: 1 | I36: 2 | L36: 3 | T36: 4 | U36: 5 | V36: 6 | W36: 7 = (4x6) | X36: 8
B37: 5 | J37: BELANJA | W37: =W38 -> 3755000
B38: 5 | C38: 1 | J38: BELANJA OPERASI | W38: =W39 -> 3755000
B39: 5 | C39: 1 | D39: 02 | J39: BELANJA BARANG DAN JASA | W39: =W40+W50 -> 3755000
B40: 5 | C40: 1 | D40: 02 | E40: 01 | J40: Belanja Barang | W40: =W41 -> 2955000
B41: 5 | C41: 1 | D41: 02 | E41: 01 | F41: 01 | J41: Belanja Barang Pakai Habis | W41: =W42 -> 2955000
B42: 5 | C42: 1 | D42: 02 | E42: 01 | F42: 01 | G42: 0026 | J42: Belanja Alat/Bahan untuk Kegiatan Kantor- Bahan Cetak | W42: =SUM(W43:W46) -> 2955000
J43: Cetak Brosur | R43: 50 | S43: lbr | T43: =R43 -> 50 | U43: lbr | V43: 2500 | W43: =V43*T43 -> 125000 | X43: BOSDA | AB43: =W43 -> 125000 | AK43: =SUM(Y43:AJ43) -> 125000 | AX43: =SUM(AL43:AW43) -> 0 | AY43: =AK43-AX43 -> 125000
J44: Cetak Banner | R44: 4 | S44: buah | T44: =R44 -> 4 | U44: buah | V44: 150000 | W44: =V44*T44 -> 600000 | X44: BOSDA | AB44: =W44 -> 600000 | AK44: =SUM(Y44:AJ44) -> 600000 | AX44: =SUM(AL44:AW44) -> 0 | AY44: =AK44-AX44 -> 600000
J45: Cetak Sertifikat | R45: 50 | S45: lbr | T45: 50 | U45: lbr | V45: 17600 | W45: =V45*T45 -> 880000 | X45: BOSDA | AA45: =W45 -> 880000 | AK45: =SUM(Y45:AJ45) -> 880000
J46: Cetak piala | R46: 3 | S46: set | T46: 3 | U46: set | V46: 450000 | W46: =V46*T46 -> 1350000 | X46: BOSDA
B50: 5 | C50: 1 | D50: 02 | E50: 02 | J50: Belanja Jasa | W50: =W51 -> 800000
B51: 5 | C51: 1 | D51: 02 | E51: 02 | F51: 01 | J51: Belanja Jasa Kantor | W51: =W52 -> 800000
B52: 5 | C52: 1 | D52: 02 | E52: 02 | F52: 01 | G52: 0004 | J52: Honorarium Tim Pelaksana Kegiatan dan Sekretariat Tim Pelaksana Kegiatan | W52: =SUM(W54:W56) -> 800000
J53: Tim PPDB
...

Sheet 5.3.2
V3: DPK-SP 5.1.1
W4: 1
A5: KOTA YOGYAKARTA
A6: TAHUN ANGGARAN 2026
A7: Satuan Pendidikan | J7: : | K7: SD Negeri Randusari
A8: Program | J8: : | K8: 5.3 Pengembangan Standar Proses
A9: Kegiatan | J9: : | K9: 5.3.2 Pembiayaan Pengembangan Perpustakaan
A10: Waktu Pelaksanaan | J10: : | K10: Januari s.d Desember
A11: Lokasi Kegiatan | J11: : | K11: SD Negeri Randusari
A12: Sumber Dana | J12: : | K12: BOSDA Rp1.080.000,00
A13: Indikator & Tolok Ukur Belanja
A14: Indikator | J14: Tolok Ukur Kinerja | V14: Target Kinerja
A15: Capaian Program | J15: :
A16: Masukan | J16: : | K16: Dana
J17: : | K17: SDM
J18: : | K18: Sarana Prasarana
J19: : | K19: Metode Kerja
A20: Keluaran | J20: : | K20: 1. Pembayaran Langganan Koran dan Majalah
A24: Hasil | J24: :
A28: Kelompok Sasaran Kegiatan | J28: :
A29: Rincian Dokumen Pelaksanaan Kegiatan Belanja
A30: Menurut Program dan Per Kegiatan Satuan Pendidikan
A31: KODE REKENING | I31: U R A I A N | L31: RINCIAN PERHITUNGAN | W31: JUMLAH | X31: Ket | Y31: tata kala perencanaan anggaran bulanan | AK31: JUMLAH | AL31: tata kala pengeluaran anggaran bulanan | AX31: JUMLAH | AY31: SISA
L33: Rincian | T33: Volume | U33: Satuan | V33: Harga Satuan
W34: (Rp) | Y34: 1 | Z34: 2 | AA34: 3 | AB34: 4 | AC34: 5 | AD34: 6 | AE34: 7 | AF34: 8 | AG34: 9 | AH34: 10 | AI34: 11 | AJ34: 12 | AL34: 1 | AM34: 2 | AN34: 3 | AO34: 4 | AP34: 5 | AQ34: 6 | AR34: 7 | AS34: 8 | AT34: 9 | AU34: 10 | AV34: 11 | AW34: 12
A36: 1 | I36: 2 | L36: 3 | T36: 4 | U36: 5 | V36: 6 | W36: 7 = (4x6) | X36: 8
B37: 5 | J37: BELANJA | W37: =W38 -> 1080000
B38: 5 | C38: 1 | J38: BELANJA OPERASI | W38: =W39 -> 1080000
B39: 5 | C39: 1 | D39: 02 | J39: BELANJA BARANG DAN JASA | W39: =W40 -> 1080000
B40: 5 | C40: 1 | D40: 02 | E40: 02 | J40: Belanja Jasa | W40: =W41 -> 1080000
B41: 5 | C41: 1 | D41: 02 | E41: 02 | F41: 01 | J41: Belanja Jasa Kantor | W41: =W42 -> 1080000
B42: 5 | C42: 1 | D42: 02 | E42: 02 | F42: 01 | G42: 0062 | J42: Belanja Langganan Jurnal/Surat Kabar/Majalah | W42: =SUM(W43:W43) -> 1080000
J43: Surat Kabar | R43: 12 | S43: bln | T43: =R43 -> 12 | U43: bln | V43: 90000 | W43: =V43*T43 -> 1080000 | X43: BOSDA | Y43: 90000 | Z43: 90000 | AA43: 90000 | AB43: 90000 | AC43: 90000 | AD43: 90000 | AE43: 90000 | AF43: 90000 | AG43: 90000 | AH43: 90000 | AI43: 90000 | AJ43: 90000 | AK43: =SUM(Y43:AJ43) -> 1080000 | AX43: =SUM(AL43:AW43) -> 0 | AY43: =AK43-AX43 -> 1080000
A46: JUMLAH | W46: =W37 -> 1080000 | AK46: =SUM(AK36:AK45) -> 1080000 | AX46: =SUM(AX36:AX45) -> 0 | AY46: =SUM(AY36:AY45) -> 1080000
A47: Rencana Penarikan Dana per Tahap
A48: Tahap 1 | D48: Rp | V48: Yogyakarta, 24 November 20254 | AA48: `
A49: Tahap 2 | D49: Rp | V49: Kepala Sekolah
A50: Tahap 3 | D50: Rp
A52: Jumlah | D52: Rp
V53: Jumadi, S.Pd.SD
...

Sheet 5.3.3
V3: DPK-SP 5.1.1
W4: 1
A5: KOTA YOGYAKARTA
A6: TAHUN ANGGARAN 2026
A7: Satuan Pendidikan | J7: : | K7: SD Negeri Randusari
A8: Program | J8: : | K8: 5.3 Pengembangan Standar Proses
A9: Kegiatan | J9: : | K9: 5.3.3 Pembiayaan Kegiatan Pembelajaran dan Ekstrakurikuler
A10: Waktu Pelaksanaan | J10: : | K10: Januari s.d Desember
A11: Lokasi Kegiatan | J11: : | K11: SD Negeri Randusari
A12: Sumber Dana | J12: : | K12: BOSDA Rp26.640.000,00
A13: Indikator & Tolok Ukur Belanja
A14: Indikator | J14: Tolok Ukur Kinerja | V14: Target Kinerja
A15: Capaian Program | J15: :
A16: Masukan | J16: : | K16: Dana
J17: : | K17: SDM
J18: : | K18: Sarana Prasarana
J19: : | K19: Metode Kerja
A20: Keluaran | J20: : | K20: 1. Pelaksanaan Ekstrakurikuler Kepramukaan
K21: 2. Pelaksanaan Ekstrakurikuler Seni dan Budaya
K22: 3. Pelaksanaan Ekstrakurikuler Olahraga
K23: 4. Pelaksanaan Program-Program Sekolah Lainnya
K24: 5. Pelaksanaan Lomba OOSN
K25: 6. Pelaksanaan Lomba FLSSN
A26: Hasil | J26: :
A30: Kelompok Sasaran Kegiatan | J30: :
A31: Rincian Dokumen Pelaksanaan Kegiatan Belanja
A32: Menurut Program dan Per Kegiatan Satuan Pendidikan
A33: KODE REKENING | I33: U R A I A N | L33: RINCIAN PERHITUNGAN | W33: JUMLAH | X33: Ket | Y33: tata kala perencanaan anggaran bulanan | AK33: JUMLAH | AL33: tata kala pengeluaran anggaran bulanan | AX33: JUMLAH | AY33: SISA
L35: Rincian | T35: Volume | U35: Satuan | V35: Harga Satuan
W36: (Rp) | Y36: 1 | Z36: 2 | AA36: 3 | AB36: 4 | AC36: 5 | AD36: 6 | AE36: 7 | AF36: 8 | AG36: 9 | AH36: 10 | AI36: 11 | AJ36: 12 | AL36: 1 | AM36: 2 | AN36: 3 | AO36: 4 | AP36: 5 | AQ36: 6 | AR36: 7 | AS36: 8 | AT36: 9 | AU36: 10 | AV36: 11 | AW36: 12
A38: 1 | I38: 2 | L38: 3 | T38: 4 | U38: 5 | V38: 6 | W38: 7 = (4x6) | X38: 8
B39: 5 | J39: BELANJA | W39: =W40 -> 47020000
B40: 5 | C40: 1 | J40: BELANJA OPERASI | W40: =W41 -> 47020000
B41: 5 | C41: 1 | D41: 02 | J41: BELANJA BARANG DAN JASA | W41: =W43 -> 47020000
B43: 5 | C43: 1 | D43: 02 | E43: 02 | J43: Belanja Jasa | W43: =W44 -> 47020000
B44: 5 | C44: 1 | D44: 02 | E44: 02 | F44: 01 | J44: Belanja Jasa Kantor | W44: =W45+W53 -> 47020000
B45: 5 | C45: 1 | D45: 02 | E45: 02 | F45: 01 | G45: 0013 | J45: Belanja Jasa Tenaga Pendidikan | W45: =SUM(W46:W51) -> 23520000
J46: Instruktur Ekstrakurikuler Pramuka | L46: 2 | M46: org | N46: x | O46: 6 | P46: jp | Q46: x | R46: 8 | S46: bln | T46: =R46*O46*L46 -> 96 | U46: ob | V46: 70000 | W46: =V46*T46 -> 6720000 | X46: BOSDA | Y46: 560000 | Z46: 560000 | AA46: 560000 | AB46: 560000 | AC46: 560000 | AD46: 560000 | AE46: 560000 | AF46: 560000 | AG46: 560000 | AH46: 560000 | AI46: 560000 | AJ46: 560000 | AK46: =SUM(Y46:AJ46) -> 6720000 | AX46: =SUM(AL46:AW46) -> 0 | AY46: =AK46-AX46 -> 6720000
J47: Instruktur Ekstrakurikuler Seni Tari | L47: 1 | M47: org | N47: x | O47: 6 | P47: jp | Q47: x | R47: 8 | S47: bln | T47: =R47*O47*L47 -> 48 | U47: ob | V47: 70000 | W47: =V47*T47 -> 3360000 | X47: BOSDA | Z47: 280000 | AA47: 280000 | AB47: 280000 | AC47: 280000 | AD47: 280000 | AE47: 280000 | AF47: 280000 | AG47: 280000 | AH47: 280000 | AI47: 280000 | AJ47: 280000 | AK47: =SUM(Y47:AJ47) -> 3080000 | AX47: =SUM(AL47:AW47) -> 0 | AY47: =AK47-AX47 -> 3080000
J48: Instruktur Ekstrakurikuler Tapak Suci | L48: 1 | M48: org | N48: x | O48: 6 | P48: jp | Q48: x | R48: 8 | S48: bln | T48: =R48*O48*L48 -> 48 | U48: ob | V48: 70000 | W48: =V48*T48 -> 3360000 | X48: BOSDA | Y48: 280000 | Z48: 280000 | AA48: 280000 | AB48: 280000 | AC48: 280000 | AD48: 280000 | AE48: 280000 | AF48: 280000 | AG48: 280000 | AH48: 280000 | AI48: 280000 | AJ48: 280000 | AK48: =SUM(Y48:AJ48) -> 3360000 | AX48: =SUM(AL48:AW48) -> 0 | AY48: =AK48-AX48 -> 3360000
...

Sheet 5.4.2
V3: DPK-SP 5.1.1
W4: 1
A5: KOTA YOGYAKARTA
A6: TAHUN ANGGARAN 2026
A7: Satuan Pendidikan | J7: : | K7: SD Negeri Randusari
A8: Program | J8: : | K8: 5.4 Pengembangan Pendidik dan Tenaga Kependidikan
A9: Kegiatan | J9: : | K9: 5.4.2 Pembiayaan Pengembangan Profesi Guru dan Tenaga Kependidikan
A10: Waktu Pelaksanaan | J10: : | K10: Januari, Mei, Juli
A11: Lokasi Kegiatan | J11: : | K11: SD Negeri Randusari
A12: Sumber Dana | J12: : | K12: BOSDA Rp10.140.000,00
A13: Indikator & Tolok Ukur Belanja
A14: Indikator | J14: Tolok Ukur Kinerja | V14: Target Kinerja
A15: Capaian Program | J15: :
A16: Masukan | J16: : | K16: Dana
J17: : | K17: SDM
J18: : | K18: Sarana Prasarana
J19: : | K19: Metode Kerja
A20: Keluaran | J20: : | K20: 1. Peningkatan Kualitas Guru Kelas, Mata Pelajaran
K21: 2. Peningkatan Kompetensi Kepala Sekolah
K22: 3. Peningkatan Kompetensi Guru untuk Keterlibatan Orangtua/Wali dan Masyarakat dalam Pembelajaran
K23: 4. Kegiatan KKG/MGMP atau KKKS/MKKS
A24: Hasil | J24: :
A28: Kelompok Sasaran Kegiatan | J28: :
A29: Rincian Dokumen Pelaksanaan Kegiatan Belanja
A30: Menurut Program dan Per Kegiatan Satuan Pendidikan
A31: KODE REKENING | I31: U R A I A N | L31: RINCIAN PERHITUNGAN | W31: JUMLAH | X31: Ket | Y31: tata kala perencanaan anggaran bulanan | AK31: JUMLAH | AL31: tata kala pengeluaran anggaran bulanan | AX31: JUMLAH | AY31: SISA
L33: Rincian | T33: Volume | U33: Satuan | V33: Harga Satuan
W34: (Rp) | Y34: 1 | Z34: 2 | AA34: 3 | AB34: 4 | AC34: 5 | AD34: 6 | AE34: 7 | AF34: 8 | AG34: 9 | AH34: 10 | AI34: 11 | AJ34: 12 | AL34: 1 | AM34: 2 | AN34: 3 | AO34: 4 | AP34: 5 | AQ34: 6 | AR34: 7 | AS34: 8 | AT34: 9 | AU34: 10 | AV34: 11 | AW34: 12
A36: 1 | I36: 2 | L36: 3 | T36: 4 | U36: 5 | V36: 6 | W36: 7 = (4x6) | X36: 8
B37: 5 | J37: BELANJA | W37: =W38 -> 10420000
B38: 5 | C38: 1 | J38: BELANJA OPERASI | W38: =W39 -> 10420000
B39: 5 | C39: 1 | D39: 02 | J39: BELANJA BARANG DAN JASA | W39: =W40 -> 10420000
B40: 5 | C40: 1 | D40: 02 | E40: 02 | J40: Belanja Jasa | W40: =W41+W52 -> 10420000
B41: 5 | C41: 1 | D41: 02 | E41: 02 | F41: 01 | J41: Belanja Jasa Kantor | W41: =W42+W46 -> 7920000
B42: 5 | C42: 1 | D42: 02 | E42: 02 | F42: 01 | G42: 0003 | J42: Honorarium Narasumber atau Pembahas, Moderator, Pembawa Acara, dan Panitia | W42: =W43+W44 -> 1400000
J43: Tokoh masyarakat | O43: 1 | P43: org | Q43: x | R43: 1 | S43: keg | T43: =R43*O43 -> 1 | U43: jam | V43: 500000 | W43: =V43*T43 -> 500000 | X43: BOSDA | AC43: 1000000 | AK43: =SUM(Y43:AJ43) -> 1000000 | AX43: =SUM(AL43:AW43) -> 0 | AY43: =AK43-AX43 -> 1000000
J44: Ahli | O44: 1 | P44: org | Q44: x | R44: 1 | S44: keg | T44: =R44*O44 -> 1 | U44: jam | V44: 900000 | W44: =V44*T44 -> 900000 | X44: BOSDA
B46: 5 | C46: 1 | D46: 02 | E46: 02 | F46: 01 | G46: 0048 | J46: Belanja Jasa Kontribusi Asosiasi | W46: =SUM(W47:W51) -> 6520000
J47: KKKS | O47: 1 | P47: org | Q47: x | R47: 1 | S47: thn | T47: =R47*O47 -> 1 | U47: thn | V47: 1900000 | W47: =V47*T47 -> 1900000 | X47: BOSDA | AE47: 1900000 | AK47: =SUM(Y47:AJ47) -> 1900000 | AX47: =SUM(AL47:AW47) -> 0 | AY47: =AK47-AX47 -> 1900000
J48: KKG Guru Kelas | O48: 6 | P48: org | Q48: x | R48: 1 | S48: thn | T48: =R48*O48 -> 6 | U48: thn | V48: 480000 | W48: =V48*T48 -> 2880000 | X48: BOSDA | AE48: 2880000 | AK48: =SUM(Y48:AJ48) -> 2880000 | AX48: =SUM(AL48:AW48) -> 0 | AY48: =AK48-AX48 -> 2880000
...

Sheet 5.5.1
V3: DPK-SP 5.1.1
W4: 1
A5: KOTA YOGYAKARTA
A6: TAHUN ANGGARAN 2026
A7: Satuan Pendidikan | J7: : | K7: SD Negeri Randusari
A8: Program | J8: : | K8: 5.5 Pengembangan Sarana dan Prasarana Sekolah
A9: Kegiatan | J9: : | K9: 5.5.1 Pembiayaan Pengembangan Perpustakaan
A10: Waktu Pelaksanaan | J10: : | K10: Januari, Juni
A11: Lokasi Kegiatan | J11: : | K11: SD Negeri Randusari
A12: Sumber Dana | J12: : | K12: BOSN Rp20.000.000,00 BOSDA Rp15.000.000,00
A13: Indikator & Tolok Ukur Belanja
A14: Indikator | J14: Tolok Ukur Kinerja | V14: Target Kinerja
A15: Capaian Program | J15: :
A16: Masukan | J16: : | K16: Dana
J17: : | K17: SDM
J18: : | K18: Sarana Prasarana
J19: : | K19: Metode Kerja
A20: Keluaran | J20: : | K20: 1. Pemeliharaan atau Pengadaan Buku/Koleksi Perpustakaan
A24: Hasil | J24: :
A28: Kelompok Sasaran Kegiatan | J28: :
A29: Rincian Dokumen Pelaksanaan Kegiatan Belanja
A30: Menurut Program dan Per Kegiatan Satuan Pendidikan
A31: KODE REKENING | I31: U R A I A N | L31: RINCIAN PERHITUNGAN | W31: JUMLAH | X31: Ket | Y31: tata kala perencanaan anggaran bulanan | AK31: JUMLAH | AL31: tata kala pengeluaran anggaran bulanan | AX31: JUMLAH | AY31: SISA
L33: Rincian | T33: Volume | U33: Satuan | V33: Harga Satuan
W34: (Rp) | Y34: 1 | Z34: 2 | AA34: 3 | AB34: 4 | AC34: 5 | AD34: 6 | AE34: 7 | AF34: 8 | AG34: 9 | AH34: 10 | AI34: 11 | AJ34: 12 | AL34: 1 | AM34: 2 | AN34: 3 | AO34: 4 | AP34: 5 | AQ34: 6 | AR34: 7 | AS34: 8 | AT34: 9 | AU34: 10 | AV34: 11 | AW34: 12
A36: 1 | I36: 2 | L36: 3 | T36: 4 | U36: 5 | V36: 6 | W36: 7 = (4x6) | X36: 8
B37: 5 | J37: BELANJA | W37: =W38 -> 15750000
B38: 5 | C38: 2 | J38: BELANJA MODAL | W38: =W39 -> 15750000
B39: 5 | C39: 2 | D39: 05 | J39: BELANJA MODAL ASET TETAP LAINNYA | W39: =W40 -> 15750000
B40: 5 | C40: 2 | D40: 05 | E40: 01 | J40: Belanja Modal Bahan Perpustakaan | W40: =W41 -> 15750000
B41: 5 | C41: 2 | D41: 05 | E41: 01 | F41: 01 | J41: Belanja Modal Bahan Perpustakaan Tercetak | W41: =W42 -> 15750000
B42: 5 | C42: 2 | D42: 05 | E42: 01 | F42: 01 | G42: 0001 | J42: Belanja Modal Buku Umum | W42: =SUM( W43:W44) -> 15750000
J43: Buku | R43: 55 | S43: eks | T43: =R43 -> 55 | U43: eks | V43: 150000 | W43: =V43*T43 -> 8250000 | X43: BOSN | Y43: =W43 -> 8250000 | AK43: =SUM(Y43:AJ43) -> 8250000 | AX43: =SUM(AL43:AW43) -> 0 | AY43: =AK43-AX43 -> 8250000
J44: Buku | R44: 50 | S44: eks | T44: =R44 -> 50 | U44: eks | V44: 150000 | W44: =V44*T44 -> 7500000 | X44: BOSDA | AD44: =W44 -> 7500000 | AK44: =SUM(Y44:AJ44) -> 7500000 | AX44: =SUM(AL44:AW44) -> 0 | AY44: =AK44-AX44 -> 7500000
A47: JUMLAH | W47: =W37 -> 15750000 | AK47: =SUM(AK36:AK46) -> 15750000 | AX47: =SUM(AX36:AX46) -> 0 | AY47: =SUM(AY36:AY46) -> 15750000
A48: Rencana Penarikan Dana per Tahap
A49: Tahap 1 | D49: Rp | V49: Yogyakarta, 24 November 2025 | AA49: `
A50: Tahap 2 | D50: Rp | V50: Kepala Sekolah
A51: Tahap 3 | D51: Rp | Z51: =W43 -> 8250000
Z52: ='5.5.5'!W44+'5.5.5'!W50+'5.5.5'!W65+'5.5.5'!W70+'5.5.5'!W73+'5.5.5'!W84+'5.5.5'!W98+'5.5.5'!W120+'5.5.5'!W102 -> 27367200
...

Sheet 5.5.3
V3: DPK-SP 5.1.1
W4: 1
A5: KOTA YOGYAKARTA
A6: TAHUN ANGGARAN 2026
A7: Satuan Pendidikan | J7: : | K7: SD Negeri Randusari
A8: Program | J8: : | K8: 5.5 Pengembangan Sarana dan Prasarana Sekolah
A9: Kegiatan | J9: : | K9: 5.5.3 Pembiayaan Administrasi Kegiatan Sekolah
A10: Waktu Pelaksanaan | J10: : | K10: Juli
A11: Lokasi Kegiatan | J11: : | K11: SD Negeri Randusari
A12: Sumber Dana | J12: : | K12: BOSDA Rp1.500.000,00
A13: Indikator & Tolok Ukur Belanja
A14: Indikator | J14: Tolok Ukur Kinerja | V14: Target Kinerja
A15: Capaian Program | J15: :
A16: Masukan | J16: : | K16: Dana
J17: : | K17: SDM
J18: : | K18: Sarana Prasarana
J19: : | K19: Metode Kerja
A20: Keluaran | J20: : | K20: 1. Pembuatan dan Pemeliharaan Website
A24: Hasil | J24: :
A28: Kelompok Sasaran Kegiatan | J28: :
A29: Rincian Dokumen Pelaksanaan Kegiatan Belanja
A30: Menurut Program dan Per Kegiatan Satuan Pendidikan
A31: KODE REKENING | I31: U R A I A N | L31: RINCIAN PERHITUNGAN | W31: JUMLAH | X31: Ket | Y31: tata kala perencanaan anggaran bulanan | AK31: JUMLAH | AL31: tata kala pengeluaran anggaran bulanan | AX31: JUMLAH | AY31: SISA
L33: Rincian | T33: Volume | U33: Satuan | V33: Harga Satuan
W34: (Rp) | Y34: 1 | Z34: 2 | AA34: 3 | AB34: 4 | AC34: 5 | AD34: 6 | AE34: 7 | AF34: 8 | AG34: 9 | AH34: 10 | AI34: 11 | AJ34: 12 | AL34: 1 | AM34: 2 | AN34: 3 | AO34: 4 | AP34: 5 | AQ34: 6 | AR34: 7 | AS34: 8 | AT34: 9 | AU34: 10 | AV34: 11 | AW34: 12
A36: 1 | I36: 2 | L36: 3 | T36: 4 | U36: 5 | V36: 6 | W36: 7 = (4x6) | X36: 8
B37: 5 | J37: BELANJA | W37: =W38 -> 1500000
B38: 5 | C38: 1 | J38: BELANJA OPERASI | W38: =W39 -> 1500000
B39: 5 | C39: 1 | D39: 02 | J39: BELANJA BARANG DAN JASA | W39: =W40 -> 1500000
B40: 5 | C40: 1 | D40: 02 | E40: 02 | J40: Belanja Jasa | W40: =W41 -> 1500000
B41: 5 | C41: 1 | D41: 02 | E41: 02 | F41: 07 | J41: Belanja Sewa Aset Tetap Lainnya | W41: =W42 -> 1500000
B42: 5 | C42: 1 | D42: 02 | E42: 02 | F42: 07 | G42: 0010 | J42: Belanja Sewa Serial | W42: =W43 -> 1500000
J43: Perpanjang Domain Website Sekolah | R43: 1 | S43: thn | T43: =R43 -> 1 | U43: thn | V43: 1500000 | W43: =V43*T43 -> 1500000 | X43: BOSDA | AE43: =W43 -> 1500000 | AK43: =SUM(Y43:AJ43) -> 1500000 | AX43: =SUM(AL43:AW43) -> 0 | AY43: =AK43-AX43 -> 1500000
A46: JUMLAH | W46: =W37 -> 1500000 | AK46: =SUM(AK36:AK45) -> 1500000 | AX46: =SUM(AX36:AX45) -> 0 | AY46: =SUM(AY36:AY45) -> 1500000
A47: Rencana Penarikan Dana per Tahap
A48: Tahap 1 | D48: Rp | V48: Yogyakarta, 24 November 2025 | AA48: `
A49: Tahap 2 | D49: Rp | V49: Kepala Sekolah
A50: Tahap 3 | D50: Rp
A52: Jumlah | D52: Rp
V53: Jumadi, S.Pd.SD
...

Sheet 5.5.5
V3: DPK-SP 5.1.1
W4: 1
A5: KOTA YOGYAKARTA
A6: TAHUN ANGGARAN 2026
A7: Satuan Pendidikan | J7: : | K7: SD Negeri Randusari
A8: Program | J8: : | K8: 5.5 Pengembangan Sarana dan Prasarana Sekolah
A9: Kegiatan | J9: : | K9: 5.5.5 Pembiayaan Pemeliharaan Sarana dan Prasarana
A10: Waktu Pelaksanaan | J10: : | K10: Januari s.d Desember
A11: Lokasi Kegiatan | J11: : | K11: SD Negeri Randusari
A12: Sumber Dana | J12: : | K12: BOSN Rp24.300.000,00 BOSDA Rp38.230.000,00
A13: Indikator & Tolok Ukur Belanja
A14: Indikator | J14: Tolok Ukur Kinerja | V14: Target Kinerja
A15: Capaian Program | J15: :
A16: Masukan | J16: : | K16: Dana
J17: : | K17: SDM
J18: : | K18: Sarana Prasarana
J19: : | K19: Metode Kerja
A20: Keluaran | J20: : | K20: 1. Pemeliharaan Perlengkapan Sekolah
K21: 2. Pengadaan Alat Peraga/Praktik Sekolah
K22: 3. Pemeliharaan Taman dan Lapangan
K23: 4. Pemeliharaan Bangunan Sekolah
K24: 5. Penambahan Lemari/Etalase
K25: 6. Pemeliharaan Peralatan Kantor
A26: Hasil | J26: :
A30: Kelompok Sasaran Kegiatan | J30: :
A31: Rincian Dokumen Pelaksanaan Kegiatan Belanja
A32: Menurut Program dan Per Kegiatan Satuan Pendidikan
A33: KODE REKENING | I33: U R A I A N | L33: RINCIAN PERHITUNGAN | W33: JUMLAH | X33: Ket | Y33: tata kala perencanaan anggaran bulanan | AK33: JUMLAH | AL33: tata kala pengeluaran anggaran bulanan | AX33: JUMLAH | AY33: SISA
L35: Rincian | T35: Volume | U35: Satuan | V35: Harga Satuan
W36: (Rp) | Y36: 1 | Z36: 2 | AA36: 3 | AB36: 4 | AC36: 5 | AD36: 6 | AE36: 7 | AF36: 8 | AG36: 9 | AH36: 10 | AI36: 11 | AJ36: 12 | AL36: 1 | AM36: 2 | AN36: 3 | AO36: 4 | AP36: 5 | AQ36: 6 | AR36: 7 | AS36: 8 | AT36: 9 | AU36: 10 | AV36: 11 | AW36: 12
A38: 1 | I38: 2 | L38: 3 | T38: 4 | U38: 5 | V38: 6 | W38: 7 = (4x6) | X38: 8
B39: 5 | J39: BELANJA | W39: =W40 -> 35261800
B40: 5 | C40: 1 | J40: BELANJA OPERASI | W40: =W41 -> 35261800
B41: 5 | C41: 1 | D41: 02 | J41: BELANJA BARANG DAN JASA | W41: =W42+W109 -> 35261800
B42: 5 | C42: 1 | D42: 02 | E42: 01 | J42: Belanja Barang | W42: =W43 -> 25267200
B43: 5 | C43: 1 | D43: 02 | E43: 01 | F43: 01 | J43: Belanja Barang Pakai Habis | W43: =W44+W50+W65+W70+W73+W84+W98+W102 -> 25267200
B44: 5 | C44: 1 | D44: 02 | E44: 01 | F44: 01 | G44: 0005 | J44: Belanja Bahan-bahan Baku Praktik KBM | W44: =SUM(W45:W48) -> 1509000
J45: Kain Mori/Bahan Batik | R45: 20 | S45: m | T45: =R45 -> 20 | U45: m | V45: 34000 | W45: =V45*T45 -> 680000 | X45: BOSN | AK45: =SUM(Y45:AJ45) -> 0 | AX45: =SUM(AL45:AW45) -> 0 | AY45: =AK45-AX45 -> 0
J46: Malam Klowong | R46: 7 | S46: buah | T46: =R46 -> 7 | U46: buah | V46: 47000 | W46: =V46*T46 -> 329000 | X46: BOSN | AK46: =SUM(Y46:AJ46) -> 0 | AX46: =SUM(AL46:AW46) -> 0 | AY46: =AK46-AX46 -> 0
J47: Pewarna Batik remasol | R47: 10 | S47: pcs | T47: =R47 -> 10 | U47: 100 gram | V47: 50000 | W47: =V47*T47 -> 500000 | X47: BOSN | AK47: =SUM(Y47:AJ47) -> 0 | AX47: =SUM(AL47:AW47) -> 0 | AY47: =AK47-AX47 -> 0
...

Sheet 5.5.7
V3: DPK-SP 5.1.1
W4: 1
A5: KOTA YOGYAKARTA
A6: TAHUN ANGGARAN 2026
A7: Satuan Pendidikan | J7: : | K7: SD Negeri Randusari
A8: Program | J8: : | K8: 5.5 Pengembangan Sarana dan Prasarana Sekolah
A9: Kegiatan | J9: : | K9: 5.5.7 Penyediaan Alat multimedia Pembelajaran
A10: Waktu Pelaksanaan | J10: : | K10: Januari, Februari, Maret
A11: Lokasi Kegiatan | J11: : | K11: SD Negeri Randusari
A12: Sumber Dana | J12: : | K12: BOSN Rp30.000.000,00 BOSDA Rp13.200.000,00
A13: Indikator & Tolok Ukur Belanja
A14: Indikator | J14: Tolok Ukur Kinerja | V14: Target Kinerja
A15: Capaian Program | J15: :
A16: Masukan | J16: : | K16: Dana
J17: : | K17: SDM
J18: : | K18: Sarana Prasarana
J19: : | K19: Metode Kerja
A20: Keluaran | J20: : | K20: 1. Pengadaan Komputer Dekstop/Work Station
K21: 2. Pengadaan Laptop
K22: 3. Pemeliharaan Printer
K23: 4. Pengadaan LCD Proyektor
A24: Hasil | J24: :
A28: Kelompok Sasaran Kegiatan | J28: :
A29: Rincian Dokumen Pelaksanaan Kegiatan Belanja
A30: Menurut Program dan Per Kegiatan Satuan Pendidikan
A31: KODE REKENING | I31: U R A I A N | L31: RINCIAN PERHITUNGAN | W31: JUMLAH | X31: Ket | Y31: tata kala perencanaan anggaran bulanan | AK31: JUMLAH | AL31: tata kala pengeluaran anggaran bulanan | AX31: JUMLAH | AY31: SISA
L33: Rincian | T33: Volume | U33: Satuan | V33: Harga Satuan
W34: (Rp) | Y34: 1 | Z34: 2 | AA34: 3 | AB34: 4 | AC34: 5 | AD34: 6 | AE34: 7 | AF34: 8 | AG34: 9 | AH34: 10 | AI34: 11 | AJ34: 12 | AL34: 1 | AM34: 2 | AN34: 3 | AO34: 4 | AP34: 5 | AQ34: 6 | AR34: 7 | AS34: 8 | AT34: 9 | AU34: 10 | AV34: 11 | AW34: 12
A36: 1 | I36: 2 | L36: 3 | T36: 4 | U36: 5 | V36: 6 | W36: 7 = (4x6) | X36: 8
B37: 5 | J37: BELANJA | W37: =W38 -> 61535400
B38: 5 | C38: 2 | J38: BELANJA MODAL | W38: =W39 -> 61535400
B39: 5 | C39: 2 | D39: 02 | J39: BELANJA MODAL PERALATAN DAN MESIN | W39: =W42+W49+W54+W61+W68 -> 61535400
B40: 5 | C40: 2 | D40: 02 | E40: 10 | J40: Belanja Modal Komputer
B41: 5 | C41: 2 | D41: 02 | E41: 10 | F41: 01 | J41: Belanja Modal Komputer Unit
B42: 5 | C42: 2 | D42: 02 | E42: 10 | F42: 01 | G42: 0002 | J42: Belanja Modal Personal Computer | W42: =SUM(W43:W44) -> 24000000
J43: Laptop core i7 | R43: 2 | S43: unit | T43: 2 | U43: unit | V43: 12000000 | W43: =T43*V43 -> 24000000 | X43: BOSN | AF43: =W43 -> 24000000 | AK43: =SUM(Y43:AJ43) -> 24000000 | AX43: =SUM(AL43:AW43) -> 0 | AY43: =AK43-AX43 -> 24000000
AC44: =W44 -> 0 | AK44: =SUM(Y44:AJ44) -> 0 | AX44: =SUM(AL44:AW44) -> 0 | AY44: =AK44-AX44 -> 0
B45: 5 | C45: 2 | J45: BELANJA MODAL | AK45: =SUM(Y45:AJ45) -> 0
B46: 5 | C46: 2 | D46: 02 | J46: BELANJA MODAL PERALATAN DAN MESIN | AK46: =SUM(Y46:AJ46) -> 0
B47: 5 | C47: 2 | D47: 02 | E47: 05 | J47: Belanja Modal Alat Kantor dan Rumah Tangga | AK47: =SUM(Y47:AJ47) -> 0
...

Sheet 5.6.2
V3: DPK-SP 5.1.1
W4: 1
A5: KOTA YOGYAKARTA
A6: TAHUN ANGGARAN 2026
A7: Satuan Pendidikan | J7: : | K7: SD Negeri Randusari
A8: Program | J8: : | K8: 5.6 Pengembangan Standar Pengelolaan
A9: Kegiatan | J9: : | K9: 5.6.2 Pembiayaan Administrasi Kegiatan Sekolah
A10: Waktu Pelaksanaan | J10: : | K10: Januari s.d Desember
A11: Lokasi Kegiatan | J11: : | K11: SD Negeri Randusari
A12: Sumber Dana | J12: : | K12: BOSDA Rp900.000,00
A13: Indikator & Tolok Ukur Belanja
A14: Indikator | J14: Tolok Ukur Kinerja | V14: Target Kinerja
A15: Capaian Program | J15: :
A16: Masukan | J16: : | K16: Dana
J17: : | K17: SDM
J18: : | K18: Sarana Prasarana
J19: : | K19: Metode Kerja
A20: Keluaran | J20: : | K20: 1. Updating Data Kesiswaan
A24: Hasil | J24: :
A28: Kelompok Sasaran Kegiatan | J28: :
A29: Rincian Dokumen Pelaksanaan Kegiatan Belanja
A30: Menurut Program dan Per Kegiatan Satuan Pendidikan
A31: KODE REKENING | I31: U R A I A N | L31: RINCIAN PERHITUNGAN | W31: JUMLAH | X31: Ket | Y31: tata kala perencanaan anggaran bulanan | AK31: JUMLAH | AL31: tata kala pengeluaran anggaran bulanan | AX31: JUMLAH | AY31: SISA
L33: Rincian | T33: Volume | U33: Satuan | V33: Harga Satuan
W34: (Rp) | Y34: 1 | Z34: 2 | AA34: 3 | AB34: 4 | AC34: 5 | AD34: 6 | AE34: 7 | AF34: 8 | AG34: 9 | AH34: 10 | AI34: 11 | AJ34: 12 | AL34: 1 | AM34: 2 | AN34: 3 | AO34: 4 | AP34: 5 | AQ34: 6 | AR34: 7 | AS34: 8 | AT34: 9 | AU34: 10 | AV34: 11 | AW34: 12
A36: 1 | I36: 2 | L36: 3 | T36: 4 | U36: 5 | V36: 6 | W36: 7 = (4x6) | X36: 8
B37: 5 | J37: BELANJA | W37: =W38 -> 7002000
B38: 5 | C38: 1 | J38: BELANJA OPERASI | W38: =W39 -> 7002000
B39: 5 | C39: 1 | D39: 02 | J39: BELANJA BARANG DAN JASA | W39: =W40 -> 7002000
B40: 5 | C40: 1 | D40: 02 | E40: 02 | J40: Belanja Jasa | W40: =W41 -> 7002000
B41: 5 | C41: 1 | D41: 02 | E41: 02 | F41: 01 | J41: Belanja Jasa Kantor | W41: =W42+W45 -> 7002000
B42: 5 | C42: 1 | D42: 02 | E42: 02 | F42: 01 | G42: 0009 | J42: Honorarium Penyelenggara Ujian | W42: =W43 -> 900000
J43: Operator Dapodik | O43: 1 | P43: org | Q43: x | R43: 12 | S43: bln | T43: =R43*O43 -> 12 | U43: ob | V43: 75000 | W43: =V43*T43 -> 900000 | X43: BOSDA | Y43: 75000 | Z43: 75000 | AA43: 75000 | AB43: 75000 | AC43: 75000 | AD43: 75000 | AE43: 75000 | AF43: 75000 | AG43: 75000 | AH43: 75000 | AI43: 75000 | AJ43: 75000 | AK43: =SUM(Y43:AJ43) -> 900000 | AX43: =SUM(AL43:AW43) -> 0 | AY43: =AK43-AX43 -> 900000
W45: =SUM(W46:W48) -> 6102000
J46: Sewa Tenda Plafon | O46: 3 | P46: unit | Q46: x | T46: 1 | U46: 3 | V46: 450000 | W46: =V46*U46 -> 1350000 | X46: BOSDA
J47: Sewa Kostum | O47: 20 | P47: set | Q47: x | T47: 1 | U47: =O47 -> 20 | V47: 180000 | W47: =U47*V47 -> 3600000 | X47: BOSDA
J48: Sewa Panggung & Karpet | O48: 24 | P48: m2 | U48: 24 | V48: 48000 | W48: =U48*V48 -> 1152000 | X48: BOSDA
A51: JUMLAH | W51: =W37 -> 7002000 | AK51: =SUM(AK36:AK50) -> 900000 | AX51: =SUM(AX36:AX50) -> 0 | AY51: =SUM(AY36:AY50) -> 900000
A52: Rencana Penarikan Dana per Tahap
A53: Tahap 1 | D53: Rp | V53: Yogyakarta, 24 November 2025 | AA53: `
...

Sheet 5.7.1
V3: DPK-SP 5.1.1
W4: 1
A5: KOTA YOGYAKARTA
A6: TAHUN ANGGARAN 2026
A7: Satuan Pendidikan | J7: : | K7: SD Negeri Randusari
A8: Program | J8: : | K8: 5.7 Pengembangan Standar Pembiayaan
A9: Kegiatan | J9: : | K9: 5.7.1 Pembiayaan Administrasi Kegiatan Sekolah
A10: Waktu Pelaksanaan | J10: : | K10: Januari, April, Juni
A11: Lokasi Kegiatan | J11: : | K11: SD Negeri Randusari
A12: Sumber Dana | J12: : | K12: BOSDA Rp17.485.000,00
A13: Indikator & Tolok Ukur Belanja
A14: Indikator | J14: Tolok Ukur Kinerja | V14: Target Kinerja
A15: Capaian Program | J15: :
A16: Masukan | J16: : | K16: Dana
J17: : | K17: SDM
J18: : | K18: Sarana Prasarana
J19: : | K19: Metode Kerja
A20: Keluaran | J20: : | K20: 1. Konsumsi Rapat Dinas
K21: 2. Penggandaan Laporan dan/atau Surat-menyurat
A24: Hasil | J24: :
A28: Kelompok Sasaran Kegiatan | J28: :
A29: Rincian Dokumen Pelaksanaan Kegiatan Belanja
A30: Menurut Program dan Per Kegiatan Satuan Pendidikan
A31: KODE REKENING | I31: U R A I A N | L31: RINCIAN PERHITUNGAN | W31: JUMLAH | X31: Ket | Y31: tata kala perencanaan anggaran bulanan | AK31: JUMLAH | AL31: tata kala pengeluaran anggaran bulanan | AX31: JUMLAH | AY31: SISA
L33: Rincian | T33: Volume | U33: Satuan | V33: Harga Satuan
W34: (Rp) | Y34: 1 | Z34: 2 | AA34: 3 | AB34: 4 | AC34: 5 | AD34: 6 | AE34: 7 | AF34: 8 | AG34: 9 | AH34: 10 | AI34: 11 | AJ34: 12 | AL34: 1 | AM34: 2 | AN34: 3 | AO34: 4 | AP34: 5 | AQ34: 6 | AR34: 7 | AS34: 8 | AT34: 9 | AU34: 10 | AV34: 11 | AW34: 12
A36: 1 | I36: 2 | L36: 3 | T36: 4 | U36: 5 | V36: 6 | W36: 7 = (4x6) | X36: 8
B37: 5 | J37: BELANJA | W37: =W38 -> 11490000
B38: 5 | C38: 1 | J38: BELANJA OPERASI | W38: =W39 -> 11490000
B39: 5 | C39: 1 | D39: 02 | J39: BELANJA BARANG DAN JASA | W39: =W40 -> 11490000
B40: 5 | C40: 1 | D40: 02 | E40: 01 | J40: Belanja Barang | W40: =W41 -> 11490000
B41: 5 | C41: 1 | D41: 02 | E41: 01 | F41: 01 | J41: Belanja Barang Pakai Habis | W41: =W45+W42 -> 11490000
B42: 5 | C42: 1 | D42: 02 | E42: 01 | F42: 01 | G42: 0026 | J42: Belanja Alat/Bahan untuk Kegiatan Kantor- Bahan Cetak | W42: =SUM(W43:W44) -> 5990000
J43: FC warna | R43: 50 | S43: lbr | T43: 50 | U43: lbr | V43: 1000 | W43: =V43*T43 -> 50000 | X43: BOSDA | Y43: 3210000 | AD43: 3210000 | AK43: =SUM(Y43:AJ43) -> 6420000 | AX43: =SUM(AL43:AW43) -> 0 | AY43: =AK43-AX43 -> 6420000
J44: FC Hitam Putih | R44: 19800 | S44: lbr | T44: 19800 | U44: lbr | V44: 300 | W44: =V44*T44 -> 5940000 | X44: BOSDA
B45: 5 | C45: 1 | D45: 02 | E45: 01 | F45: 01 | G45: 0052 | J45: Belanja Makanan dan Minuman Rapat | W45: =SUM(W46:W47) -> 5500000
J46: Snack (1 tahun) | R46: 500 | S46: org | T46: =R46 -> 500 | U46: os | V46: 11000 | W46: =V46*T46 -> 5500000 | X46: BOSDA | Y46: 1100000 | AK46: =SUM(Y46:AJ46) -> 1100000 | AX46: =SUM(AL46:AW46) -> 0 | AY46: =AK46-AX46 -> 1100000
Y47: 7245000 | AK47: =SUM(Y47:AJ47) -> 7245000 | AX47: =SUM(AL47:AW47) -> 0 | AY47: =AK47-AX47 -> 7245000
A49: JUMLAH | W49: =W37 -> 11490000 | AK49: =SUM(AK36:AK48) -> 14765000 | AX49: =SUM(AX36:AX48) -> 0 | AY49: =SUM(AY36:AY48) -> 14765000
A50: Rencana Penarikan Dana per Tahap
...

Sheet 5.7.2
V3: DPK-SP 5.1.1
W4: 1
A5: KOTA YOGYAKARTA
A6: TAHUN ANGGARAN 2026
A7: Satuan Pendidikan | J7: : | K7: SD Negeri Randusari
A8: Program | J8: : | K8: 5.7 Pengembangan Standar Pembiayaan
A9: Kegiatan | J9: : | K9: 5.7.2 Pembiayaan Langganan Daya dan/atau Jasa
A10: Waktu Pelaksanaan | J10: : | K10: Januari s.d Desember
A11: Lokasi Kegiatan | J11: : | K11: SD Negeri Randusari
A12: Sumber Dana | J12: : | K12: BOSN Rp12.180.000,00 BOSDA Rp900.000,00
A13: Indikator & Tolok Ukur Belanja
A14: Indikator | J14: Tolok Ukur Kinerja | V14: Target Kinerja
A15: Capaian Program | J15: :
A16: Masukan | J16: : | K16: Dana
J17: : | K17: SDM
J18: : | K18: Sarana Prasarana
J19: : | K19: Metode Kerja
A20: Keluaran | J20: : | K20: 1. Pembayaran Rek listrik
K21: 2. Pembayaran Rek telepon
K22: 3. Pembayaran langganan internet
A24: Hasil | J24: :
A28: Kelompok Sasaran Kegiatan | J28: :
A29: Rincian Dokumen Pelaksanaan Kegiatan Belanja
A30: Menurut Program dan Per Kegiatan Satuan Pendidikan
A31: KODE REKENING | I31: U R A I A N | L31: RINCIAN PERHITUNGAN | W31: JUMLAH | X31: Ket | Y31: tata kala perencanaan anggaran bulanan | AK31: JUMLAH | AL31: tata kala pengeluaran anggaran bulanan | AX31: JUMLAH | AY31: SISA
L33: Rincian | T33: Volume | U33: Satuan | V33: Harga Satuan
W34: (Rp) | Y34: 1 | Z34: 2 | AA34: 3 | AB34: 4 | AC34: 5 | AD34: 6 | AE34: 7 | AF34: 8 | AG34: 9 | AH34: 10 | AI34: 11 | AJ34: 12 | AL34: 1 | AM34: 2 | AN34: 3 | AO34: 4 | AP34: 5 | AQ34: 6 | AR34: 7 | AS34: 8 | AT34: 9 | AU34: 10 | AV34: 11 | AW34: 12
A36: 1 | I36: 2 | L36: 3 | T36: 4 | U36: 5 | V36: 6 | W36: 7 = (4x6) | X36: 8
B37: 5 | J37: BELANJA | W37: =W38 -> 13722800
B38: 5 | C38: 1 | J38: BELANJA OPERASI | W38: =W39 -> 13722800
B39: 5 | C39: 1 | D39: 02 | J39: BELANJA BARANG DAN JASA | W39: =W40 -> 13722800
B40: 5 | C40: 1 | D40: 02 | E40: 02 | J40: Belanja Jasa | W40: =W41 -> 13722800
B41: 5 | C41: 1 | D41: 02 | E41: 02 | F41: 01 | J41: Belanja Jasa Kantor | W41: =W42+W45+W48 -> 13722800
B42: 5 | C42: 1 | D42: 02 | E42: 02 | F42: 01 | G42: 0059 | J42: Belanja Tagihan Telepon | W42: =W43 -> 7222800
J43: Tagihan Telepon dan Internet | R43: 12 | S43: bln | T43: =R43 -> 12 | U43: bln | V43: 601900 | W43: =V43*T43 -> 7222800 | X43: BOSN | Y43: 605000 | Z43: 605000 | AA43: 605000 | AB43: 605000 | AC43: 605000 | AD43: 605000 | AE43: 605000 | AF43: 605000 | AG43: 605000 | AH43: 605000 | AI43: 605000 | AJ43: 605000 | AK43: =SUM(Y43:AJ43) -> 7260000 | AX43: =SUM(AL43:AW43) -> 0 | AY43: =AK43-AX43 -> 7260000
B45: 5 | C45: 1 | D45: 02 | E45: 02 | F45: 01 | G45: 0061 | J45: Belanja Alat/Bahan untuk Kegiatan Kantor- Alat Tulis Kantor | W45: =W46 -> 5160000
J46: Tagihan Listrik | R46: 12 | S46: bln | T46: =R46 -> 12 | U46: bln | V46: 430000 | W46: =V46*T46 -> 5160000 | X46: BOSN | Y46: 420000 | Z46: 420000 | AA46: 420000 | AB46: 420000 | AC46: 420000 | AD46: 420000 | AE46: 420000 | AF46: 420000 | AG46: 420000 | AH46: 420000 | AI46: 420000 | AJ46: 420000 | AK46: =SUM(Y46:AJ46) -> 5040000 | AX46: =SUM(AL46:AW46) -> 0 | AY46: =AK46-AX46 -> 5040000
B48: 5 | C48: 1 | D48: 02 | E48: 02 | F48: 01 | G48: 0067 | J48: Belanja Pembayaran Pajak, Bea, dan Perizinan | W48: =SUM(W49:W50) -> 1340000
J49: Retribusi Pengelolaan Sampah DLH Pemkot Yk | R49: 1 | S49: thn | T49: =R49 -> 1 | U49: thn | V49: 500000 | W49: =V49*T49 -> 500000 | X49: BOSDA | Y49: =W49 -> 500000 | AK49: =SUM(Y49:AJ49) -> 500000 | AX49: =SUM(AL49:AW49) -> 0 | AY49: =AK49-AX49 -> 500000
J50: Retribusi Sampah Bulanan Sekolah | R50: 12 | S50: bln | T50: =R50 -> 12 | U50: bln | V50: 70000 | W50: =V50*T50 -> 840000 | X50: BOSDA | Y50: 70000 | Z50: 70000 | AA50: 70000 | AB50: 70000 | AC50: 60000 | AD50: 60000 | AE50: 60000 | AF50: 60000 | AG50: 60000 | AH50: 60000 | AI50: 60000 | AJ50: 60000 | AK50: =SUM(Y50:AJ50) -> 760000 | AX50: =SUM(AL50:AW50) -> 0 | AY50: =AK50-AX50 -> 760000
...

Sheet 5.7.5
V3: DPK-SP 5.1.1
W4: 1
A5: KOTA YOGYAKARTA
A6: TAHUN ANGGARAN 2026
A7: Satuan Pendidikan | J7: : | K7: SD Negeri Randusari
A8: Program | J8: : | K8: 5.7 Pengembangan Standar Pembiayaan
A9: Kegiatan | J9: : | K9: 5.7.5 Pembiayaan untuk Pembayaran Honor
A10: Waktu Pelaksanaan | J10: : | K10: Januari s.d Desember
A11: Lokasi Kegiatan | J11: : | K11: SD Negeri Randusari
A12: Sumber Dana | J12: : | K12: BOSDA Rp13.800.000,00
A13: Indikator & Tolok Ukur Belanja
A14: Indikator | J14: Tolok Ukur Kinerja | V14: Target Kinerja
A15: Capaian Program | J15: :
A16: Masukan | J16: : | K16: Dana
J17: : | K17: SDM
J18: : | K18: Sarana Prasarana
J19: : | K19: Metode Kerja
A20: Keluaran | J20: : | K20: 1. Pembayaran Honor Tenaga Administrasi
K21: 2. Gaji dan Tunjangan ASN
A24: Hasil | J24: :
A28: Kelompok Sasaran Kegiatan | J28: :
A29: Rincian Dokumen Pelaksanaan Kegiatan Belanja
A30: Menurut Program dan Per Kegiatan Satuan Pendidikan
A31: KODE REKENING | I31: U R A I A N | L31: RINCIAN PERHITUNGAN | W31: JUMLAH | X31: Ket | Y31: tata kala perencanaan anggaran bulanan | AK31: JUMLAH | AL31: tata kala pengeluaran anggaran bulanan | AX31: JUMLAH | AY31: SISA
L33: Rincian | T33: Volume | U33: Satuan | V33: Harga Satuan
W34: (Rp) | Y34: 1 | Z34: 2 | AA34: 3 | AB34: 4 | AC34: 5 | AD34: 6 | AE34: 7 | AF34: 8 | AG34: 9 | AH34: 10 | AI34: 11 | AJ34: 12 | AL34: 1 | AM34: 2 | AN34: 3 | AO34: 4 | AP34: 5 | AQ34: 6 | AR34: 7 | AS34: 8 | AT34: 9 | AU34: 10 | AV34: 11 | AW34: 12
A36: 1 | I36: 2 | L36: 3 | T36: 4 | U36: 5 | V36: 6 | W36: 7 = (4x6) | X36: 8
B37: 5 | J37: BELANJA | W37: =W38 -> 11100000
B38: 5 | C38: 1 | J38: BELANJA OPERASI | W38: =W48+W39 -> 11100000
B39: 5 | C39: 1 | D39: 01 | J39: BELANJA PEGAWAI | W39: =W40 -> 4200000
B40: 5 | C40: 1 | D40: 01 | E40: 03 | J40: Tambahan Penghasilan berdasarkan Pertimbangan Objektif Lainnya ASN | W40: =W41 -> 4200000
B41: 5 | C41: 1 | D41: 01 | E41: 03 | F41: 07 | J41: Belanja Honorarium | W41: =W45+W42 -> 4200000
B42: 5 | C42: 1 | D42: 01 | E42: 03 | F42: 07 | G42: 0001 | J42: Pengelola Keuangan | W42: =W43 -> 2400000
J43: Pengelola Sekolah - Bendahara | O43: 1 | P43: org | Q43: x | R43: 12 | S43: bln | T43: =O43*R43 -> 12 | U43: ob | V43: 200000 | W43: =T43*V43 -> 2400000 | X43: BOSDA | Y43: 200000 | Z43: 200000 | AA43: 200000 | AB43: 200000 | AC43: 200000 | AD43: 200000 | AE43: 200000 | AF43: 200000 | AG43: 200000 | AH43: 200000 | AI43: 200000 | AJ43: 200000 | AK43: =SUM(Y43:AJ43) -> 2400000 | AX43: =SUM(AL43:AW43) -> 0 | AY43: =AK43-AX43 -> 2400000
B45: 5 | C45: 1 | D45: 01 | E45: 03 | F45: 07 | G45: 0002 | J45: Pengurus Barang | W45: =W46 -> 1800000
J46: Honor Pengurus Barang Pembantu Sekolah | O46: 1 | P46: org | Q46: x | R46: 12 | S46: bln | T46: =O46*R46 -> 12 | U46: ob | V46: 150000 | W46: =T46*V46 -> 1800000 | X46: BOSDA | Y46: 150000 | Z46: 150000 | AA46: 150000 | AB46: 150000 | AC46: 150000 | AD46: 150000 | AE46: 150000 | AF46: 150000 | AG46: 150000 | AH46: 150000 | AI46: 150000 | AJ46: 150000 | AK46: =SUM(Y46:AJ46) -> 1800000 | AX46: =SUM(AL46:AW46) -> 0 | AY46: =AK46-AX46 -> 1800000
B48: 5 | C48: 1 | D48: 02 | J48: BELANJA BARANG DAN JASA | W48: =W49 -> 6900000
B49: 5 | C49: 1 | D49: 02 | E49: 02 | J49: Belanja Jasa | W49: =W50 -> 6900000
B50: 5 | C50: 1 | D50: 02 | E50: 02 | F50: 01 | J50: Belanja Jasa Kantor | W50: =W51 -> 6900000
B51: 5 | C51: 1 | D51: 02 | E51: 02 | F51: 01 | G51: 0013 | J51: Belanja Jasa Tenaga Pendidikan | W51: =SUM(W52:W53) -> 6900000
...

Sheet 5.8
V3: DPK-SP 5.1.1
W4: 1
A5: KOTA YOGYAKARTA
A6: TAHUN ANGGARAN 2026
A7: Satuan Pendidikan | J7: : | K7: SD Negeri Randusari
A8: Program | J8: : | K8: 5.8 Pengembangan dan Implementasi Sistem Penilaian
A9: Kegiatan | J9: : | K9: 5.8.2 Kegiatan Pembiayaan Asesmen/Evaluasi Pembelajaran dan Ekstrakurikuler
A10: Waktu Pelaksanaan | J10: : | K10: Januari s.d Desember
A11: Lokasi Kegiatan | J11: : | K11: SD Negeri Randusari
A12: Sumber Dana | J12: : | K12: BOSDA Rp8.050.000,00
A13: Indikator & Tolok Ukur Belanja
A14: Indikator | J14: Tolok Ukur Kinerja | V14: Target Kinerja
A15: Capaian Program | J15: :
A16: Masukan | J16: : | K16: Dana
J17: : | K17: SDM
J18: : | K18: Sarana Prasarana
J19: : | K19: Metode Kerja
A20: Keluaran | J20: : | K20: 1. Penyusunan Kisi-kisi Ujian Sekolah
K21: 2. Penyusunan Soal Ujian Sekolah
K22: 3. Pelaksanaan Penilaian Ujian Sekolah
K23: 4. Simulasi dan Pelaksanaan Ujian Nasional Berbasis Komputer (UNBK)
A24: Hasil | J24: :
A28: Kelompok Sasaran Kegiatan | J28: :
A29: Rincian Dokumen Pelaksanaan Kegiatan Belanja
A30: Menurut Program dan Per Kegiatan Satuan Pendidikan
A31: KODE REKENING | I31: U R A I A N | L31: RINCIAN PERHITUNGAN | W31: JUMLAH | X31: Ket | Y31: tata kala perencanaan anggaran bulanan | AK31: JUMLAH | AL31: tata kala pengeluaran anggaran bulanan | AX31: JUMLAH | AY31: SISA
L33: Rincian | T33: Volume | U33: Satuan | V33: Harga Satuan
W34: (Rp) | Y34: 1 | Z34: 2 | AA34: 3 | AB34: 4 | AC34: 5 | AD34: 6 | AE34: 7 | AF34: 8 | AG34: 9 | AH34: 10 | AI34: 11 | AJ34: 12 | AL34: 1 | AM34: 2 | AN34: 3 | AO34: 4 | AP34: 5 | AQ34: 6 | AR34: 7 | AS34: 8 | AT34: 9 | AU34: 10 | AV34: 11 | AW34: 12
A36: 1 | I36: 2 | L36: 3 | T36: 4 | U36: 5 | V36: 6 | W36: 7 = (4x6) | X36: 8
B37: 5 | J37: BELANJA | W37: =W38 -> 2000000
B38: 5 | C38: 1 | J38: BELANJA OPERASI | W38: =W39 -> 2000000
B39: 5 | C39: 1 | D39: 02 | J39: BELANJA BARANG DAN JASA | W39: =W40 -> 2000000
B40: 5 | C40: 1 | D40: 02 | E40: 02 | J40: Belanja Jasa | W40: =W41 -> 2000000
B41: 5 | C41: 1 | D41: 02 | E41: 02 | F41: 01 | J41: Belanja Jasa Kantor | W41: =W43 -> 2000000
B43: 5 | C43: 1 | D43: 02 | E43: 02 | F43: 01 | G43: 0039 | J43: Belanja Jasa Tenaga Informasi dan Teknologi | W43: =SUM(W44:W49) -> 2000000
J44: ASPD
J45: Proktor | O45: 1 | P45: org | Q45: x | R45: 3 | S45: hr | T45: =O45*R45 -> 3 | U45: oh | V45: 200000 | W45: =T45*V45 -> 600000 | X45: BOSDA | AC45: 600000 | AK45: =SUM(Y45:AJ45) -> 600000 | AX45: =SUM(AL45:AW45) -> 0 | AY45: =AK45-AX45 -> 600000
J46: Teknisi | O46: 1 | P46: org | Q46: x | R46: 3 | S46: hr | T46: =O46*R46 -> 3 | U46: oh | V46: 200000 | W46: =T46*V46 -> 600000 | X46: BOSDA | AC46: 600000 | AK46: =SUM(Y46:AJ46) -> 600000 | AX46: =SUM(AL46:AW46) -> 0 | AY46: =AK46-AX46 -> 600000
J47: ANBK
J48: Proktor | O48: 1 | P48: org | Q48: x | R48: 2 | S48: hr | T48: =O48*R48 -> 2 | U48: oh | V48: 200000 | W48: =T48*V48 -> 400000 | X48: BOSDA | AH48: 400000 | AK48: =SUM(Y48:AJ48) -> 400000 | AX48: =SUM(AL48:AW48) -> 0 | AY48: =AK48-AX48 -> 400000
...

Sheet ProKeg
A1: PROGRAM DAN KEGIATAN APBS
A4: Kode | B4: Program | C4: Kegiatan | D4: Keluaran | E4: Target
A5: 5.1.1 | B5: Pengembangan Kompetensi Lulusan | C5: Pembiaayaan Kegiatan Pembelajaran dan Ekstrakurikuler | D5: Pelaksanaan Uji Coba US/USB Tk. Kecamatan | E5: …siswa
D6: Pelaksanaan Uji Coba US/USB Tk. Kabupaten/Kota | E6: …siswa
D7: Pemantapan persiapan ujian/Tryout | E7: …siswa
D8: Pengayaan TIK untuk memfasilitasi kegiatan pembelajaran | E8: …siswa
D9: Pengembangan diri : TIK sebagai wahana kreativitas dari inovasi | E9: …siswa
D10: Pengembangan diri : TIK untuk meningkatkan integritas kebangsaan | E10: …siswa
D11: Pengembangan diri : pemanfaatan perpustakaan sekolah | E11: …siswa
D12: Pengembangan diri : melaksanakan perilaku hidup bersih dan sehat/Pendidikan dan pengembangan sekolah sehat, aman, ramah anak, dan menyenangkan | E12: …siswa
D13: Penyelenggaraan : pencegahan penyalahgunaan narkotika, psikotropika, zat adiktif (narkoba), minuman keras, merokok, dan HIV AIDS | E13: …siswa
D14: Pengembangan diri : Meningkatkan kesehatan reproduksi remaja | E14: …siswa
D15: Penyelenggaraan : Melaksanakan kegiatan orientasi siswa baru yang bersifat akademik dan pengenalan lingkungan tanpa kekerasan | E15: …siswa
D16: Penyelenggaraan : Melaksanakan penghijauan dan perindangan lingkungan sekolah | E16: …siswa
D17: Penyelenggaraan : Melaksanakan kegiatan 7 K | E17: …siswa
... D26: Penyelenggaraan pembelajaran aktif kreatid efektif dan nyaman | E26: …siswa
A27: 5.2.1 | B27: Pengembangan Standar Isi | C27: Pembiayaan Pengembangan Perpustakaan | D27: Penyusunan Program Perpustakaan | E27: …program
A28: 5.2.2 | C28: Pembiaayaan Kegiatan Pembelajaran dan Ekstrakurikuler | D28: Penyusunan Pembagian Tugas Guru dan Jadwal Pelajaran | E28: …dokumen
D29: Penyusunan program Tahunan | E29: …dokumen
D30: Penyusunan program Semester | E30: …dokumen
D31: Penyusunan Silabus | E31: …dokumen
D32: Penyusunan RPP | E32: …dokumen
D33: Penyusunan Program BP/BK | E33: …dokumen
D34: Penyusunan Program Pengelolaan Laboratorium IPA | E34: …dokumen
